Internal Server Error: /admin/data/series/
Traceback (most recent call last):
  File "/home/theo/acaciadata.com/django/local/lib/python2.7/site-packages/django/core/handlers/base.py", line 112, in get_response
    response = wrapped_callback(request, *callback_args, **callback_kwargs)
  File "/home/theo/acaciadata.com/django/local/lib/python2.7/site-packages/django/contrib/admin/options.py", line 432, in wrapper
    return self.admin_site.admin_view(view)(*args, **kwargs)
  File "/home/theo/acaciadata.com/django/local/lib/python2.7/site-packages/django/utils/decorators.py", line 99, in _wrapped_view
    response = view_func(request, *args, **kwargs)
  File "/home/theo/acaciadata.com/django/local/lib/python2.7/site-packages/django/views/decorators/cache.py", line 52, in _wrapped_view_func
    response = view_func(request, *args, **kwargs)
  File "/home/theo/acaciadata.com/django/local/lib/python2.7/site-packages/django/contrib/admin/sites.py", line 198, in inner
    return view(request, *args, **kwargs)
  File "/home/theo/acaciadata.com/django/local/lib/python2.7/site-packages/django/utils/decorators.py", line 29, in _wrapper
    return bound_func(*args, **kwargs)
  File "/home/theo/acaciadata.com/django/local/lib/python2.7/site-packages/django/utils/decorators.py", line 99, in _wrapped_view
    response = view_func(request, *args, **kwargs)
  File "/home/theo/acaciadata.com/django/local/lib/python2.7/site-packages/django/utils/decorators.py", line 25, in bound_func
    return func(self, *args2, **kwargs2)
  File "/home/theo/acaciadata.com/django/local/lib/python2.7/site-packages/django/contrib/admin/options.py", line 1306, in changelist_view
    self)
  File "/home/theo/acaciadata.com/django/local/lib/python2.7/site-packages/django/contrib/admin/views/main.py", line 105, in __init__
    self.queryset = self.get_queryset(request)
  File "/home/theo/acaciadata.com/django/local/lib/python2.7/site-packages/django/contrib/admin/views/main.py", line 356, in get_queryset
    filters_use_distinct) = self.get_filters(request)
  File "/home/theo/acaciadata.com/django/local/lib/python2.7/site-packages/django/contrib/admin/views/main.py", line 178, in get_filters
    self.model, self.model_admin, field_path=field_path)
  File "/home/theo/acaciadata.com/django/local/lib/python2.7/site-packages/django/contrib/admin/filters.py", line 155, in create
    model, model_admin, field_path=field_path)
  File "/home/theo/acaciadata.com/django/local/lib/python2.7/site-packages/django/contrib/admin/filters.py", line 170, in __init__
    self.lookup_choices = field.get_choices(include_blank=False)
  File "/home/theo/acaciadata.com/django/local/lib/python2.7/site-packages/django/db/models/fields/__init__.py", line 462, in get_choices
    self.rel.limit_choices_to)]
  File "/home/theo/acaciadata.com/django/local/lib/python2.7/site-packages/django/db/models/query.py", line 96, in __iter__
    self._fetch_all()
  File "/home/theo/acaciadata.com/django/local/lib/python2.7/site-packages/django/db/models/query.py", line 857, in _fetch_all
    self._result_cache = list(self.iterator())
  File "/home/theo/acaciadata.com/django/local/lib/python2.7/site-packages/django/db/models/query.py", line 220, in iterator
    for row in compiler.results_iter():
  File "/home/theo/acaciadata.com/django/local/lib/python2.7/site-packages/django/db/models/sql/compiler.py", line 713, in results_iter
    for rows in self.execute_sql(MULTI):
  File "/home/theo/acaciadata.com/django/local/lib/python2.7/site-packages/django/db/models/sql/compiler.py", line 786, in execute_sql
    cursor.execute(sql, params)
  File "/home/theo/acaciadata.com/django/local/lib/python2.7/site-packages/django/db/backends/util.py", line 69, in execute
    return super(CursorDebugWrapper, self).execute(sql, params)
  File "/home/theo/acaciadata.com/django/local/lib/python2.7/site-packages/django/db/backends/util.py", line 53, in execute
    return self.cursor.execute(sql, params)
  File "/home/theo/acaciadata.com/django/local/lib/python2.7/site-packages/django/db/utils.py", line 99, in __exit__
    six.reraise(dj_exc_type, dj_exc_value, traceback)
  File "/home/theo/acaciadata.com/django/local/lib/python2.7/site-packages/django/db/backends/util.py", line 53, in execute
    return self.cursor.execute(sql, params)
  File "/home/theo/acaciadata.com/django/local/lib/python2.7/site-packages/django/db/backends/mysql/base.py", line 124, in execute
    return self.cursor.execute(query, args)
  File "/home/theo/acaciadata.com/django/local/lib/python2.7/site-packages/MySQLdb/cursors.py", line 205, in execute
    self.errorhandler(self, exc, value)
  File "/home/theo/acaciadata.com/django/local/lib/python2.7/site-packages/MySQLdb/connections.py", line 36, in defaulterrorhandler
    raise errorclass, errorvalue
OperationalError: (1054, "Unknown column 'data_datasource.timezone' in 'field list'")
