Not Found: /home/data
Internal Server Error: /home
Traceback (most recent call last):
  File "/home/theo/acaciadata.com/django/local/lib/python2.7/site-packages/django/core/handlers/base.py", line 88, in get_response
    response = middleware_method(request)
  File "/home/theo/acaciadata.com/django/local/lib/python2.7/site-packages/django/middleware/common.py", line 71, in process_request
    if (not urlresolvers.is_valid_path(request.path_info, urlconf) and
  File "/home/theo/acaciadata.com/django/local/lib/python2.7/site-packages/django/core/urlresolvers.py", line 596, in is_valid_path
    resolve(path, urlconf)
  File "/home/theo/acaciadata.com/django/local/lib/python2.7/site-packages/django/core/urlresolvers.py", line 476, in resolve
    return get_resolver(urlconf).resolve(path)
  File "/home/theo/acaciadata.com/django/local/lib/python2.7/site-packages/django/core/urlresolvers.py", line 337, in resolve
    for pattern in self.url_patterns:
  File "/home/theo/acaciadata.com/django/local/lib/python2.7/site-packages/django/core/urlresolvers.py", line 365, in url_patterns
    patterns = getattr(self.urlconf_module, "urlpatterns", self.urlconf_module)
  File "/home/theo/acaciadata.com/django/local/lib/python2.7/site-packages/django/core/urlresolvers.py", line 360, in urlconf_module
    self._urlconf_module = import_module(self.urlconf_name)
  File "/home/theo/acaciadata.com/django/local/lib/python2.7/site-packages/django/utils/importlib.py", line 40, in import_module
    __import__(name)
  File "/home/theo/acaciadata.com/workspace/texel/texel/urls.py", line 8, in <module>
    url(r'^$',ProjectDetailView.as_view(pk=1),'home'),
  File "/home/theo/acaciadata.com/django/local/lib/python2.7/site-packages/django/views/generic/base.py", line 60, in as_view
    "attributes of the class." % (cls.__name__, key))
TypeError: ProjectDetailView() received an invalid keyword 'pk'. as_view only accepts arguments that are already attributes of the class.
Internal Server Error: /home
Traceback (most recent call last):
  File "/home/theo/acaciadata.com/django/local/lib/python2.7/site-packages/django/core/handlers/base.py", line 88, in get_response
    response = middleware_method(request)
  File "/home/theo/acaciadata.com/django/local/lib/python2.7/site-packages/django/middleware/common.py", line 71, in process_request
    if (not urlresolvers.is_valid_path(request.path_info, urlconf) and
  File "/home/theo/acaciadata.com/django/local/lib/python2.7/site-packages/django/core/urlresolvers.py", line 596, in is_valid_path
    resolve(path, urlconf)
  File "/home/theo/acaciadata.com/django/local/lib/python2.7/site-packages/django/core/urlresolvers.py", line 476, in resolve
    return get_resolver(urlconf).resolve(path)
  File "/home/theo/acaciadata.com/django/local/lib/python2.7/site-packages/django/core/urlresolvers.py", line 337, in resolve
    for pattern in self.url_patterns:
  File "/home/theo/acaciadata.com/django/local/lib/python2.7/site-packages/django/core/urlresolvers.py", line 365, in url_patterns
    patterns = getattr(self.urlconf_module, "urlpatterns", self.urlconf_module)
  File "/home/theo/acaciadata.com/django/local/lib/python2.7/site-packages/django/core/urlresolvers.py", line 360, in urlconf_module
    self._urlconf_module = import_module(self.urlconf_name)
  File "/home/theo/acaciadata.com/django/local/lib/python2.7/site-packages/django/utils/importlib.py", line 40, in import_module
    __import__(name)
  File "/home/theo/acaciadata.com/workspace/texel/texel/urls.py", line 8, in <module>
    url(r'^$',ProjectDetailView(pk=1).as_view(),'home'),
  File "/home/theo/acaciadata.com/django/local/lib/python2.7/site-packages/django/utils/decorators.py", line 11, in __get__
    raise AttributeError("This method is available only on the view class.")
AttributeError: This method is available only on the view class.
Internal Server Error: /
Traceback (most recent call last):
  File "/home/theo/acaciadata.com/django/local/lib/python2.7/site-packages/django/core/handlers/base.py", line 99, in get_response
    resolver_match = resolver.resolve(request.path_info)
  File "/home/theo/acaciadata.com/django/local/lib/python2.7/site-packages/django/core/urlresolvers.py", line 339, in resolve
    sub_match = pattern.resolve(new_path)
  File "/home/theo/acaciadata.com/django/local/lib/python2.7/site-packages/django/core/urlresolvers.py", line 221, in resolve
    kwargs.update(self.default_args)
ValueError: dictionary update sequence element #0 has length 1; 2 is required
