Not Found: /
Not Found: /favicon.ico
Internal Server Error: /
Traceback (most recent call last):
  File "/home/theo/acaciadata.com/django/local/lib/python2.7/site-packages/django/core/handlers/base.py", line 112, in get_response
    response = wrapped_callback(request, *callback_args, **callback_kwargs)
  File "/home/theo/acaciadata.com/django/local/lib/python2.7/site-packages/django/views/generic/base.py", line 69, in view
    return self.dispatch(request, *args, **kwargs)
  File "/home/theo/acaciadata.com/django/local/lib/python2.7/site-packages/django/views/generic/base.py", line 87, in dispatch
    return handler(request, *args, **kwargs)
  File "/home/theo/acaciadata.com/django/local/lib/python2.7/site-packages/django/views/generic/detail.py", line 110, in get
    self.object = self.get_object()
  File "/home/theo/acaciadata.com/molenwaard/molenwaard/views.py", line 11, in get_object
    return Network.objects.get(name = 'Molenwaard')
  File "/home/theo/acaciadata.com/django/local/lib/python2.7/site-packages/django/db/models/manager.py", line 151, in get
    return self.get_queryset().get(*args, **kwargs)
  File "/home/theo/acaciadata.com/django/local/lib/python2.7/site-packages/django/db/models/query.py", line 310, in get
    self.model._meta.object_name)
DoesNotExist: Network matching query does not exist.
Internal Server Error: /
Traceback (most recent call last):
  File "/home/theo/acaciadata.com/django/local/lib/python2.7/site-packages/django/core/handlers/base.py", line 112, in get_response
    response = wrapped_callback(request, *callback_args, **callback_kwargs)
  File "/home/theo/acaciadata.com/django/local/lib/python2.7/site-packages/django/views/generic/base.py", line 69, in view
    return self.dispatch(request, *args, **kwargs)
  File "/home/theo/acaciadata.com/django/local/lib/python2.7/site-packages/django/views/generic/base.py", line 87, in dispatch
    return handler(request, *args, **kwargs)
  File "/home/theo/acaciadata.com/django/local/lib/python2.7/site-packages/django/views/generic/detail.py", line 110, in get
    self.object = self.get_object()
  File "/home/theo/acaciadata.com/molenwaard/molenwaard/views.py", line 11, in get_object
    return Network.objects.get(name = 'Molenwaard')
  File "/home/theo/acaciadata.com/django/local/lib/python2.7/site-packages/django/db/models/manager.py", line 151, in get
    return self.get_queryset().get(*args, **kwargs)
  File "/home/theo/acaciadata.com/django/local/lib/python2.7/site-packages/django/db/models/query.py", line 310, in get
    self.model._meta.object_name)
DoesNotExist: Network matching query does not exist.
Internal Server Error: /
Traceback (most recent call last):
  File "/home/theo/acaciadata.com/django/local/lib/python2.7/site-packages/django/core/handlers/base.py", line 112, in get_response
    response = wrapped_callback(request, *callback_args, **callback_kwargs)
  File "/home/theo/acaciadata.com/django/local/lib/python2.7/site-packages/django/views/generic/base.py", line 69, in view
    return self.dispatch(request, *args, **kwargs)
  File "/home/theo/acaciadata.com/django/local/lib/python2.7/site-packages/django/views/generic/base.py", line 87, in dispatch
    return handler(request, *args, **kwargs)
  File "/home/theo/acaciadata.com/django/local/lib/python2.7/site-packages/django/views/generic/detail.py", line 110, in get
    self.object = self.get_object()
  File "/home/theo/acaciadata.com/molenwaard/molenwaard/views.py", line 11, in get_object
    return Network.objects.get(name = 'Molenwaard')
  File "/home/theo/acaciadata.com/django/local/lib/python2.7/site-packages/django/db/models/manager.py", line 151, in get
    return self.get_queryset().get(*args, **kwargs)
  File "/home/theo/acaciadata.com/django/local/lib/python2.7/site-packages/django/db/models/query.py", line 310, in get
    self.model._meta.object_name)
DoesNotExist: Network matching query does not exist.
